2024-01-01 03:40:54.746 WARNING (SyncWorker_0) [homeassistant.loader] We found a custom integration breaking_changes which has not been tested by Home Assistant. This component might cause stability problems, be sure to disable it if you experience issues with Home Assistant
2024-01-01 03:40:54.751 WARNING (SyncWorker_0) [homeassistant.loader] We found a custom integration plex_recently_added which has not been tested by Home Assistant. This component might cause stability problems, be sure to disable it if you experience issues with Home Assistant
2024-01-01 03:40:54.753 WARNING (SyncWorker_0) [homeassistant.loader] We found a custom integration manish which has not been tested by Home Assistant. This component might cause stability problems, be sure to disable it if you experience issues with Home Assistant
2024-01-01 03:40:54.759 WARNING (SyncWorker_0) [homeassistant.loader] We found a custom integration plex_assistant which has not been tested by Home Assistant. This component might cause stability problems, be sure to disable it if you experience issues with Home Assistant
2024-01-01 03:40:54.761 WARNING (SyncWorker_0) [homeassistant.loader] We found a custom integration anniversaries which has not been tested by Home Assistant. This component might cause stability problems, be sure to disable it if you experience issues with Home Assistant
2024-01-01 03:40:54.763 WARNING (SyncWorker_0) [homeassistant.loader] We found a custom integration ourgroceries which has not been tested by Home Assistant. This component might cause stability problems, be sure to disable it if you experience issues with Home Assistant
2024-01-01 03:40:54.770 WARNING (SyncWorker_0) [homeassistant.loader] We found a custom integration average which has not been tested by Home Assistant. This component might cause stability problems, be sure to disable it if you experience issues with Home Assistant
2024-01-01 03:40:54.773 WARNING (SyncWorker_0) [homeassistant.loader] We found a custom integration afvalinfo which has not been tested by Home Assistant. This component might cause stability problems, be sure to disable it if you experience issues with Home Assistant
2024-01-01 03:40:54.776 WARNING (SyncWorker_0) [homeassistant.loader] We found a custom integration car_wash which has not been tested by Home Assistant. This component might cause stability problems, be sure to disable it if you experience issues with Home Assistant
2024-01-01 03:40:54.778 WARNING (SyncWorker_0) [homeassistant.loader] We found a custom integration saver which has not been tested by Home Assistant. This component might cause stability problems, be sure to disable it if you experience issues with Home Assistant
2024-01-01 03:40:54.781 WARNING (SyncWorker_0) [homeassistant.loader] We found a custom integration buienalarm which has not been tested by Home Assistant. This component might cause stability problems, be sure to disable it if you experience issues with Home Assistant
2024-01-01 03:40:54.783 WARNING (SyncWorker_0) [homeassistant.loader] We found a custom integration hacs which has not been tested by Home Assistant. This component might cause stability problems, be sure to disable it if you experience issues with Home Assistant
2024-01-01 03:40:54.785 WARNING (SyncWorker_0) [homeassistant.loader] We found a custom integration favicon which has not been tested by Home Assistant. This component might cause stability problems, be sure to disable it if you experience issues with Home Assistant
2024-01-01 03:40:54.787 WARNING (SyncWorker_0) [homeassistant.loader] We found a custom integration temperature_feels_like which has not been tested by Home Assistant. This component might cause stability problems, be sure to disable it if you experience issues with Home Assistant
2024-01-01 03:40:54.788 WARNING (SyncWorker_0) [homeassistant.loader] We found a custom integration illuminance which has not been tested by Home Assistant. This component might cause stability problems, be sure to disable it if you experience issues with Home Assistant
2024-01-01 03:40:54.791 WARNING (SyncWorker_0) [homeassistant.loader] We found a custom integration hpprinter which has not been tested by Home Assistant. This component might cause stability problems, be sure to disable it if you experience issues with Home Assistant
2024-01-01 03:40:54.794 WARNING (SyncWorker_0) [homeassistant.loader] We found a custom integration fontawesome which has not been tested by Home Assistant. This component might cause stability problems, be sure to disable it if you experience issues with Home Assistant
2024-01-01 03:40:54.796 WARNING (SyncWorker_0) [homeassistant.loader] We found a custom integration pyscript which has not been tested by Home Assistant. This component might cause stability problems, be sure to disable it if you experience issues with Home Assistant
2024-01-01 03:40:54.798 WARNING (SyncWorker_0) [homeassistant.loader] We found a custom integration simpleicons which has not been tested by Home Assistant. This component might cause stability problems, be sure to disable it if you experience issues with Home Assistant
2024-01-01 03:40:54.801 WARNING (SyncWorker_0) [homeassistant.loader] We found a custom integration google_home which has not been tested by Home Assistant. This component might cause stability problems, be sure to disable it if you experience issues with Home Assistant
2024-01-01 03:40:54.803 WARNING (SyncWorker_0) [homeassistant.loader] We found a custom integration afvalbeheer which has not been tested by Home Assistant. This component might cause stability problems, be sure to disable it if you experience issues with Home Assistant
2024-01-01 03:40:54.805 WARNING (SyncWorker_0) [homeassistant.loader] We found a custom integration worlds_air_quality_index which has not been tested by Home Assistant. This component might cause stability problems, be sure to disable it if you experience issues with Home Assistant
2024-01-01 03:40:54.808 WARNING (SyncWorker_0) [homeassistant.loader] We found a custom integration knmi which has not been tested by Home Assistant. This component might cause stability problems, be sure to disable it if you experience issues with Home Assistant
2024-01-01 03:40:54.810 WARNING (SyncWorker_0) [homeassistant.loader] We found a custom integration google_photos which has not been tested by Home Assistant. This component might cause stability problems, be sure to disable it if you experience issues with Home Assistant
2024-01-01 03:40:54.812 WARNING (SyncWorker_0) [homeassistant.loader] We found a custom integration n26 which has not been tested by Home Assistant. This component might cause stability problems, be sure to disable it if you experience issues with Home Assistant
2024-01-01 03:40:54.812 ERROR (SyncWorker_0) [homeassistant.loader] The custom integration 'n26' does not have a version key in the manifest file and was blocked from loading. See https://developers.home-assistant.io/blog/2021/01/29/custom-integration-changes#versions for more details
2024-01-01 03:40:54.815 WARNING (SyncWorker_0) [homeassistant.loader] We found a custom integration whatspie which has not been tested by Home Assistant. This component might cause stability problems, be sure to disable it if you experience issues with Home Assistant
2024-01-01 03:40:54.817 WARNING (SyncWorker_0) [homeassistant.loader] We found a custom integration lg_hombot which has not been tested by Home Assistant. This component might cause stability problems, be sure to disable it if you experience issues with Home Assistant
2024-01-01 03:40:54.820 WARNING (SyncWorker_0) [homeassistant.loader] We found a custom integration pollenprognos which has not been tested by Home Assistant. This component might cause stability problems, be sure to disable it if you experience issues with Home Assistant
2024-01-01 03:40:54.823 WARNING (SyncWorker_0) [homeassistant.loader] We found a custom integration jokes which has not been tested by Home Assistant. This component might cause stability problems, be sure to disable it if you experience issues with Home Assistant
2024-01-01 03:40:54.830 WARNING (SyncWorker_0) [homeassistant.loader] We found a custom integration localtuya which has not been tested by Home Assistant. This component might cause stability problems, be sure to disable it if you experience issues with Home Assistant
2024-01-01 03:40:54.832 WARNING (SyncWorker_0) [homeassistant.loader] We found a custom integration auto_backup which has not been tested by Home Assistant. This component might cause stability problems, be sure to disable it if you experience issues with Home Assistant
2024-01-01 03:40:54.835 WARNING (SyncWorker_0) [homeassistant.loader] We found a custom integration spotcast which has not been tested by Home Assistant. This component might cause stability problems, be sure to disable it if you experience issues with Home Assistant
2024-01-01 03:41:37.847 ERROR (MainThread) [homeassistant.helpers.template] Template variable error: 'None' has no attribute 'attributes' when rendering '{{ states.vacuum.hombot.attributes.battery_icon }}'
2024-01-01 03:41:41.126 WARNING (MainThread) [homeassistant.helpers.template] Template variable warning: 'None' has no attribute 'last_changed' when rendering 'last_changed: {{states.sensor.neerslag_buienalarm_regen_data.last_changed}}'
2024-01-01 03:41:41.185 ERROR (SyncWorker_3) [homeassistant.components.command_line.utils] Command failed (with return code 1): python3 -c "import requests; import json; import random; dataRequest = requests.get('https://gpsgadget.buienradar.nl/data/raintext?lat=51.83&lon=5.86&c='+str(random.randint(0,999999999999999)) ).text; dataRequest = dataRequest.replace('\r\n',' '); data = '{\"data\":\"'+dataRequest+'\"}';    pri(data);"
2024-01-01 03:41:41.187 WARNING (MainThread) [homeassistant.components.command_line] Empty reply found when expecting JSON data
2024-01-01 03:42:02.083 ERROR (SyncWorker_5) [glocaltokens.client] [!] Could not get access token.
2024-01-01 03:42:06.864 WARNING (MainThread) [homeassistant.bootstrap] Waiting on integrations to complete setup: google_home
2024-01-01 03:42:53.818 WARNING (SyncWorker_0) [py.warnings] /usr/local/lib/python3.11/site-packages/urllib3/connectionpool.py:1061: InsecureRequestWarning: Unverified HTTPS request is being made to host '192.168.69.103'. Adding certificate verification is strongly advised. See: https://urllib3.readthedocs.io/en/1.26.x/advanced-usage.html#ssl-warnings
  warnings.warn(

2024-01-01 03:42:53.846 WARNING (SyncWorker_0) [py.warnings] /usr/local/lib/python3.11/site-packages/urllib3/connectionpool.py:1061: InsecureRequestWarning: Unverified HTTPS request is being made to host '192.168.69.103'. Adding certificate verification is strongly advised. See: https://urllib3.readthedocs.io/en/1.26.x/advanced-usage.html#ssl-warnings
  warnings.warn(

2024-01-01 03:42:54.976 WARNING (SyncWorker_4) [py.warnings] /usr/local/lib/python3.11/site-packages/urllib3/connectionpool.py:1061: InsecureRequestWarning: Unverified HTTPS request is being made to host '192.168.69.103'. Adding certificate verification is strongly advised. See: https://urllib3.readthedocs.io/en/1.26.x/advanced-usage.html#ssl-warnings
  warnings.warn(

2024-01-01 03:42:54.988 WARNING (SyncWorker_5) [py.warnings] /usr/local/lib/python3.11/site-packages/urllib3/connectionpool.py:1061: InsecureRequestWarning: Unverified HTTPS request is being made to host '192.168.69.103'. Adding certificate verification is strongly advised. See: https://urllib3.readthedocs.io/en/1.26.x/advanced-usage.html#ssl-warnings
  warnings.warn(

2024-01-01 03:42:55.086 WARNING (SyncWorker_9) [py.warnings] /usr/local/lib/python3.11/site-packages/urllib3/connectionpool.py:1061: InsecureRequestWarning: Unverified HTTPS request is being made to host '192.168.69.103'. Adding certificate verification is strongly advised. See: https://urllib3.readthedocs.io/en/1.26.x/advanced-usage.html#ssl-warnings
  warnings.warn(

2024-01-01 03:42:55.095 WARNING (SyncWorker_9) [py.warnings] /usr/local/lib/python3.11/site-packages/urllib3/connectionpool.py:1061: InsecureRequestWarning: Unverified HTTPS request is being made to host '192.168.69.103'. Adding certificate verification is strongly advised. See: https://urllib3.readthedocs.io/en/1.26.x/advanced-usage.html#ssl-warnings
  warnings.warn(

2024-01-01 03:42:55.131 WARNING (SyncWorker_5) [py.warnings] /usr/local/lib/python3.11/site-packages/urllib3/connectionpool.py:1061: InsecureRequestWarning: Unverified HTTPS request is being made to host '192.168.69.103'. Adding certificate verification is strongly advised. See: https://urllib3.readthedocs.io/en/1.26.x/advanced-usage.html#ssl-warnings
  warnings.warn(

2024-01-01 03:42:56.291 WARNING (SyncWorker_3) [py.warnings] /usr/local/lib/python3.11/site-packages/urllib3/connectionpool.py:1061: InsecureRequestWarning: Unverified HTTPS request is being made to host '192.168.69.103'. Adding certificate verification is strongly advised. See: https://urllib3.readthedocs.io/en/1.26.x/advanced-usage.html#ssl-warnings
  warnings.warn(

2024-01-01 03:42:56.298 WARNING (SyncWorker_3) [py.warnings] /usr/local/lib/python3.11/site-packages/urllib3/connectionpool.py:1061: InsecureRequestWarning: Unverified HTTPS request is being made to host '192.168.69.103'. Adding certificate verification is strongly advised. See: https://urllib3.readthedocs.io/en/1.26.x/advanced-usage.html#ssl-warnings
  warnings.warn(

2024-01-01 03:43:08.916 WARNING (MainThread) [homeassistant.bootstrap] Waiting on integrations to complete setup: mqtt
2024-01-01 03:44:11.194 WARNING (MainThread) [homeassistant.bootstrap] Waiting on integrations to complete setup: mqtt, ping
2024-01-01 03:45:11.258 WARNING (MainThread) [homeassistant.bootstrap] Waiting on integrations to complete setup: mqtt, ping
2024-01-01 03:45:12.850 WARNING (SyncWorker_0) [py.warnings] /usr/local/lib/python3.11/site-packages/urllib3/connectionpool.py:1061: InsecureRequestWarning: Unverified HTTPS request is being made to host '192.168.69.103'. Adding certificate verification is strongly advised. See: https://urllib3.readthedocs.io/en/1.26.x/advanced-usage.html#ssl-warnings
  warnings.warn(

2024-01-01 03:45:12.868 WARNING (SyncWorker_0) [py.warnings] /usr/local/lib/python3.11/site-packages/urllib3/connectionpool.py:1061: InsecureRequestWarning: Unverified HTTPS request is being made to host '192.168.69.103'. Adding certificate verification is strongly advised. See: https://urllib3.readthedocs.io/en/1.26.x/advanced-usage.html#ssl-warnings
  warnings.warn(

2024-01-01 03:45:12.903 WARNING (SyncWorker_0) [py.warnings] /usr/local/lib/python3.11/site-packages/urllib3/connectionpool.py:1061: InsecureRequestWarning: Unverified HTTPS request is being made to host '192.168.69.103'. Adding certificate verification is strongly advised. See: https://urllib3.readthedocs.io/en/1.26.x/advanced-usage.html#ssl-warnings
  warnings.warn(

2024-01-01 03:45:12.924 WARNING (SyncWorker_0) [py.warnings] /usr/local/lib/python3.11/site-packages/urllib3/connectionpool.py:1061: InsecureRequestWarning: Unverified HTTPS request is being made to host '192.168.69.103'. Adding certificate verification is strongly advised. See: https://urllib3.readthedocs.io/en/1.26.x/advanced-usage.html#ssl-warnings
  warnings.warn(

2024-01-01 03:45:12.954 WARNING (SyncWorker_0) [py.warnings] /usr/local/lib/python3.11/site-packages/urllib3/connectionpool.py:1061: InsecureRequestWarning: Unverified HTTPS request is being made to host '192.168.69.103'. Adding certificate verification is strongly advised. See: https://urllib3.readthedocs.io/en/1.26.x/advanced-usage.html#ssl-warnings
  warnings.warn(

2024-01-01 03:45:13.143 WARNING (SyncWorker_0) [py.warnings] /usr/local/lib/python3.11/site-packages/urllib3/connectionpool.py:1061: InsecureRequestWarning: Unverified HTTPS request is being made to host '192.168.69.103'. Adding certificate verification is strongly advised. See: https://urllib3.readthedocs.io/en/1.26.x/advanced-usage.html#ssl-warnings
  warnings.warn(

2024-01-01 03:45:13.150 WARNING (SyncWorker_0) [py.warnings] /usr/local/lib/python3.11/site-packages/urllib3/connectionpool.py:1061: InsecureRequestWarning: Unverified HTTPS request is being made to host '192.168.69.103'. Adding certificate verification is strongly advised. See: https://urllib3.readthedocs.io/en/1.26.x/advanced-usage.html#ssl-warnings
  warnings.warn(

2024-01-01 03:45:13.158 WARNING (SyncWorker_0) [py.warnings] /usr/local/lib/python3.11/site-packages/urllib3/connectionpool.py:1061: InsecureRequestWarning: Unverified HTTPS request is being made to host '192.168.69.103'. Adding certificate verification is strongly advised. See: https://urllib3.readthedocs.io/en/1.26.x/advanced-usage.html#ssl-warnings
  warnings.warn(

2024-01-01 03:45:13.175 WARNING (SyncWorker_0) [py.warnings] /usr/local/lib/python3.11/site-packages/urllib3/connectionpool.py:1061: InsecureRequestWarning: Unverified HTTPS request is being made to host '192.168.69.103'. Adding certificate verification is strongly advised. See: https://urllib3.readthedocs.io/en/1.26.x/advanced-usage.html#ssl-warnings
  warnings.warn(

2024-01-01 03:45:13.629 ERROR (MainThread) [homeassistant.helpers.integration_platform] Error processing platform plex_assistant.intent
Traceback (most recent call last):
  File "/usr/src/homeassistant/homeassistant/helpers/integration_platform.py", line 61, in _async_process_single_integration_platform_component
    await integration_platform.process_platform(hass, component_name, platform)
  File "/usr/src/homeassistant/homeassistant/components/intent/__init__.py", line 254, in _async_process_intent
    await platform.async_setup_intents(hass)
  File "/config/custom_components/plex_assistant/intent.py", line 9, in async_setup_intents
    hass.components.conversation.async_register(
    ^^^^^^^^^^^^^^^^^^^^^^^^^^^^^^^^^^^^^^^^^^^
  File "/usr/src/homeassistant/homeassistant/loader.py", line 1067, in __getattr__
    value = getattr(self._module, attr)
            ^^^^^^^^^^^^^^^^^^^^^^^^^^^
AttributeError: module 'homeassistant.components.conversation' has no attribute 'async_register'
2024-01-01 03:45:35.092 ERROR (MainThread) [homeassistant.helpers.event] Error while processing template: Template<template=({{ (states.sensor.desk_light_button_device_temperature.state | float - 8 ) | round(0) }}) renders=2>
Traceback (most recent call last):
  File "/usr/src/homeassistant/homeassistant/helpers/template.py", line 1926, in forgiving_float_filter
    return float(value)
           ^^^^^^^^^^^^
ValueError: could not convert string to float: 'unknown'

During handling of the above exception, another exception occurred:

Traceback (most recent call last):
  File "/usr/src/homeassistant/homeassistant/helpers/template.py", line 569, in async_render
    render_result = _render_with_context(self.template, compiled, **kwargs)
                    ^^^^^^^^^^^^^^^^^^^^^^^^^^^^^^^^^^^^^^^^^^^^^^^^^^^^^^^
  File "/usr/src/homeassistant/homeassistant/helpers/template.py", line 2247, in _render_with_context
    return template.render(**kwargs)
           ^^^^^^^^^^^^^^^^^^^^^^^^^
  File "/usr/local/lib/python3.11/site-packages/jinja2/environment.py", line 1301, in render
    self.environment.handle_exception()
  File "/usr/local/lib/python3.11/site-packages/jinja2/environment.py", line 936, in handle_exception
    raise rewrite_traceback_stack(source=source)
  File "<template>", line 1, in top-level template code
  File "/usr/src/homeassistant/homeassistant/helpers/template.py", line 1929, in forgiving_float_filter
    raise_no_default("float", value)
  File "/usr/src/homeassistant/homeassistant/helpers/template.py", line 1627, in raise_no_default
    raise ValueError(
ValueError: Template error: float got invalid input 'unknown' when rendering template '{{ (states.sensor.desk_light_button_device_temperature.state | float - 8 ) | round(0) }}' but no default was specified

The above exception was the direct cause of the following exception:

Traceback (most recent call last):
  File "/usr/src/homeassistant/homeassistant/helpers/template.py", line 695, in async_render_to_info
    render_info._result = self.async_render(
                          ^^^^^^^^^^^^^^^^^^
  File "/usr/src/homeassistant/homeassistant/helpers/template.py", line 571, in async_render
    raise TemplateError(err) from err
homeassistant.exceptions.TemplateError: ValueError: Template error: float got invalid input 'unknown' when rendering template '{{ (states.sensor.desk_light_button_device_temperature.state | float - 8 ) | round(0) }}' but no default was specified
2024-01-01 03:45:35.108 ERROR (MainThread) [homeassistant.components.template.template_entity] TemplateError('ValueError: Template error: float got invalid input 'unknown' when rendering template '{{ (states.sensor.desk_light_button_device_temperature.state | float - 8 ) | round(0) }}' but no default was specified') while processing template 'Template<template=({{ (states.sensor.desk_light_button_device_temperature.state | float - 8 ) | round(0) }}) renders=4>' for attribute '_attr_native_value' in entity 'sensor.desk_temp_adj'
2024-01-01 03:45:35.111 ERROR (MainThread) [homeassistant.helpers.event] Error while processing template: Template<template=({{ (states.sensor.front_door_sensor_device_temperature.state | float - 3 ) | round(0) }}) renders=2>
Traceback (most recent call last):
  File "/usr/src/homeassistant/homeassistant/helpers/template.py", line 1926, in forgiving_float_filter
    return float(value)
           ^^^^^^^^^^^^
ValueError: could not convert string to float: 'unknown'

During handling of the above exception, another exception occurred:

Traceback (most recent call last):
  File "/usr/src/homeassistant/homeassistant/helpers/template.py", line 569, in async_render
    render_result = _render_with_context(self.template, compiled, **kwargs)
                    ^^^^^^^^^^^^^^^^^^^^^^^^^^^^^^^^^^^^^^^^^^^^^^^^^^^^^^^
  File "/usr/src/homeassistant/homeassistant/helpers/template.py", line 2247, in _render_with_context
    return template.render(**kwargs)
           ^^^^^^^^^^^^^^^^^^^^^^^^^
  File "/usr/local/lib/python3.11/site-packages/jinja2/environment.py", line 1301, in render
    self.environment.handle_exception()
  File "/usr/local/lib/python3.11/site-packages/jinja2/environment.py", line 936, in handle_exception
    raise rewrite_traceback_stack(source=source)
  File "<template>", line 1, in top-level template code
  File "/usr/src/homeassistant/homeassistant/helpers/template.py", line 1929, in forgiving_float_filter
    raise_no_default("float", value)
  File "/usr/src/homeassistant/homeassistant/helpers/template.py", line 1627, in raise_no_default
    raise ValueError(
ValueError: Template error: float got invalid input 'unknown' when rendering template '{{ (states.sensor.front_door_sensor_device_temperature.state | float - 3 ) | round(0) }}' but no default was specified

The above exception was the direct cause of the following exception:

Traceback (most recent call last):
  File "/usr/src/homeassistant/homeassistant/helpers/template.py", line 695, in async_render_to_info
    render_info._result = self.async_render(
                          ^^^^^^^^^^^^^^^^^^
  File "/usr/src/homeassistant/homeassistant/helpers/template.py", line 571, in async_render
    raise TemplateError(err) from err
homeassistant.exceptions.TemplateError: ValueError: Template error: float got invalid input 'unknown' when rendering template '{{ (states.sensor.front_door_sensor_device_temperature.state | float - 3 ) | round(0) }}' but no default was specified
2024-01-01 03:45:35.122 ERROR (MainThread) [homeassistant.components.template.template_entity] TemplateError('ValueError: Template error: float got invalid input 'unknown' when rendering template '{{ (states.sensor.front_door_sensor_device_temperature.state | float - 3 ) | round(0) }}' but no default was specified') while processing template 'Template<template=({{ (states.sensor.front_door_sensor_device_temperature.state | float - 3 ) | round(0) }}) renders=4>' for attribute '_attr_native_value' in entity 'sensor.front_door_sensor_device_temperature_adj'
2024-01-01 03:45:35.123 ERROR (MainThread) [homeassistant.helpers.event] Error while processing template: Template<template=({{ (states.sensor.living_room_window_sensor_device_temperature.state | float - 4 ) | round(0) }}) renders=2>
Traceback (most recent call last):
  File "/usr/src/homeassistant/homeassistant/helpers/template.py", line 1926, in forgiving_float_filter
    return float(value)
           ^^^^^^^^^^^^
ValueError: could not convert string to float: 'unknown'

During handling of the above exception, another exception occurred:

Traceback (most recent call last):
  File "/usr/src/homeassistant/homeassistant/helpers/template.py", line 569, in async_render
    render_result = _render_with_context(self.template, compiled, **kwargs)
                    ^^^^^^^^^^^^^^^^^^^^^^^^^^^^^^^^^^^^^^^^^^^^^^^^^^^^^^^
  File "/usr/src/homeassistant/homeassistant/helpers/template.py", line 2247, in _render_with_context
    return template.render(**kwargs)
           ^^^^^^^^^^^^^^^^^^^^^^^^^
  File "/usr/local/lib/python3.11/site-packages/jinja2/environment.py", line 1301, in render
    self.environment.handle_exception()
  File "/usr/local/lib/python3.11/site-packages/jinja2/environment.py", line 936, in handle_exception
    raise rewrite_traceback_stack(source=source)
  File "<template>", line 1, in top-level template code
  File "/usr/src/homeassistant/homeassistant/helpers/template.py", line 1929, in forgiving_float_filter
    raise_no_default("float", value)
  File "/usr/src/homeassistant/homeassistant/helpers/template.py", line 1627, in raise_no_default
    raise ValueError(
ValueError: Template error: float got invalid input 'unknown' when rendering template '{{ (states.sensor.living_room_window_sensor_device_temperature.state | float - 4 ) | round(0) }}' but no default was specified

The above exception was the direct cause of the following exception:

Traceback (most recent call last):
  File "/usr/src/homeassistant/homeassistant/helpers/template.py", line 695, in async_render_to_info
    render_info._result = self.async_render(
                          ^^^^^^^^^^^^^^^^^^
  File "/usr/src/homeassistant/homeassistant/helpers/template.py", line 571, in async_render
    raise TemplateError(err) from err
homeassistant.exceptions.TemplateError: ValueError: Template error: float got invalid input 'unknown' when rendering template '{{ (states.sensor.living_room_window_sensor_device_temperature.state | float - 4 ) | round(0) }}' but no default was specified
2024-01-01 03:45:35.134 ERROR (MainThread) [homeassistant.components.template.template_entity] TemplateError('ValueError: Template error: float got invalid input 'unknown' when rendering template '{{ (states.sensor.living_room_window_sensor_device_temperature.state | float - 4 ) | round(0) }}' but no default was specified') while processing template 'Template<template=({{ (states.sensor.living_room_window_sensor_device_temperature.state | float - 4 ) | round(0) }}) renders=4>' for attribute '_attr_native_value' in entity 'sensor.living_room_window_sensor_device_temperature_adj'
2024-01-01 03:45:35.135 ERROR (MainThread) [homeassistant.helpers.template] Template variable error: 'None' has no attribute 'attributes' when rendering '{{ states.vacuum.hombot.attributes.battery_level }}'
2024-01-01 03:45:35.136 ERROR (MainThread) [homeassistant.helpers.event] Error while processing template: Template<template=({{ states.vacuum.hombot.attributes.battery_level }}) renders=2>
Traceback (most recent call last):
  File "/usr/src/homeassistant/homeassistant/helpers/template.py", line 569, in async_render
    render_result = _render_with_context(self.template, compiled, **kwargs)
                    ^^^^^^^^^^^^^^^^^^^^^^^^^^^^^^^^^^^^^^^^^^^^^^^^^^^^^^^
  File "/usr/src/homeassistant/homeassistant/helpers/template.py", line 2247, in _render_with_context
    return template.render(**kwargs)
           ^^^^^^^^^^^^^^^^^^^^^^^^^
  File "/usr/local/lib/python3.11/site-packages/jinja2/environment.py", line 1301, in render
    self.environment.handle_exception()
  File "/usr/local/lib/python3.11/site-packages/jinja2/environment.py", line 936, in handle_exception
    raise rewrite_traceback_stack(source=source)
  File "<template>", line 1, in top-level template code
  File "/usr/local/lib/python3.11/site-packages/jinja2/sandbox.py", line 326, in getattr
    value = getattr(obj, attribute)
            ^^^^^^^^^^^^^^^^^^^^^^^
  File "/usr/src/homeassistant/homeassistant/helpers/template.py", line 2282, in _fail_with_undefined_error
    raise ex
  File "/usr/src/homeassistant/homeassistant/helpers/template.py", line 2279, in _fail_with_undefined_error
    return super()._fail_with_undefined_error(*args, **kwargs)
           ^^^^^^^^^^^^^^^^^^^^^^^^^^^^^^^^^^^^^^^^^^^^^^^^^^^
jinja2.exceptions.UndefinedError: 'None' has no attribute 'attributes'

The above exception was the direct cause of the following exception:

Traceback (most recent call last):
  File "/usr/src/homeassistant/homeassistant/helpers/template.py", line 695, in async_render_to_info
    render_info._result = self.async_render(
                          ^^^^^^^^^^^^^^^^^^
  File "/usr/src/homeassistant/homeassistant/helpers/template.py", line 571, in async_render
    raise TemplateError(err) from err
homeassistant.exceptions.TemplateError: UndefinedError: 'None' has no attribute 'attributes'
2024-01-01 03:45:35.147 ERROR (MainThread) [homeassistant.helpers.template] Template variable error: 'None' has no attribute 'attributes' when rendering '{{ states.vacuum.hombot.attributes.battery_icon }}'
2024-01-01 03:45:35.148 ERROR (MainThread) [homeassistant.helpers.event] Error while processing template: Template<template=({{ states.vacuum.hombot.attributes.battery_icon }}) renders=3>
Traceback (most recent call last):
  File "/usr/src/homeassistant/homeassistant/helpers/template.py", line 569, in async_render
    render_result = _render_with_context(self.template, compiled, **kwargs)
                    ^^^^^^^^^^^^^^^^^^^^^^^^^^^^^^^^^^^^^^^^^^^^^^^^^^^^^^^
  File "/usr/src/homeassistant/homeassistant/helpers/template.py", line 2247, in _render_with_context
    return template.render(**kwargs)
           ^^^^^^^^^^^^^^^^^^^^^^^^^
  File "/usr/local/lib/python3.11/site-packages/jinja2/environment.py", line 1301, in render
    self.environment.handle_exception()
  File "/usr/local/lib/python3.11/site-packages/jinja2/environment.py", line 936, in handle_exception
    raise rewrite_traceback_stack(source=source)
  File "<template>", line 1, in top-level template code
  File "/usr/local/lib/python3.11/site-packages/jinja2/sandbox.py", line 326, in getattr
    value = getattr(obj, attribute)
            ^^^^^^^^^^^^^^^^^^^^^^^
  File "/usr/src/homeassistant/homeassistant/helpers/template.py", line 2282, in _fail_with_undefined_error
    raise ex
  File "/usr/src/homeassistant/homeassistant/helpers/template.py", line 2279, in _fail_with_undefined_error
    return super()._fail_with_undefined_error(*args, **kwargs)
           ^^^^^^^^^^^^^^^^^^^^^^^^^^^^^^^^^^^^^^^^^^^^^^^^^^^
jinja2.exceptions.UndefinedError: 'None' has no attribute 'attributes'

The above exception was the direct cause of the following exception:

Traceback (most recent call last):
  File "/usr/src/homeassistant/homeassistant/helpers/template.py", line 695, in async_render_to_info
    render_info._result = self.async_render(
                          ^^^^^^^^^^^^^^^^^^
  File "/usr/src/homeassistant/homeassistant/helpers/template.py", line 571, in async_render
    raise TemplateError(err) from err
homeassistant.exceptions.TemplateError: UndefinedError: 'None' has no attribute 'attributes'
2024-01-01 03:45:35.158 ERROR (MainThread) [homeassistant.helpers.template] Template variable error: 'None' has no attribute 'attributes' when rendering '{{ states.vacuum.hombot.attributes.battery_level }}'
2024-01-01 03:45:35.160 ERROR (MainThread) [homeassistant.helpers.template] Template variable error: 'None' has no attribute 'attributes' when rendering '{{ states.vacuum.hombot.attributes.battery_icon }}'
2024-01-01 03:45:35.161 ERROR (MainThread) [homeassistant.components.template.template_entity] TemplateError('UndefinedError: 'None' has no attribute 'attributes'') while processing template 'Template<template=({{ states.vacuum.hombot.attributes.battery_level }}) renders=4>' for attribute '_attr_native_value' in entity 'sensor.hombot_battery'
2024-01-01 03:45:35.161 ERROR (MainThread) [homeassistant.components.template.template_entity] TemplateError('UndefinedError: 'None' has no attribute 'attributes'') while processing template 'Template<template=({{ states.vacuum.hombot.attributes.battery_icon }}) renders=5>' for attribute '_attr_icon' in entity 'sensor.hombot_battery'
2024-01-01 03:45:35.162 ERROR (MainThread) [homeassistant.helpers.template] Template variable error: 'None' has no attribute 'attributes' when rendering '{{ states.vacuum.hombot.attributes.status }}'
2024-01-01 03:45:35.163 ERROR (MainThread) [homeassistant.helpers.event] Error while processing template: Template<template=({{ states.vacuum.hombot.attributes.status }}) renders=2>
Traceback (most recent call last):
  File "/usr/src/homeassistant/homeassistant/helpers/template.py", line 569, in async_render
    render_result = _render_with_context(self.template, compiled, **kwargs)
                    ^^^^^^^^^^^^^^^^^^^^^^^^^^^^^^^^^^^^^^^^^^^^^^^^^^^^^^^
  File "/usr/src/homeassistant/homeassistant/helpers/template.py", line 2247, in _render_with_context
    return template.render(**kwargs)
           ^^^^^^^^^^^^^^^^^^^^^^^^^
  File "/usr/local/lib/python3.11/site-packages/jinja2/environment.py", line 1301, in render
    self.environment.handle_exception()
  File "/usr/local/lib/python3.11/site-packages/jinja2/environment.py", line 936, in handle_exception
    raise rewrite_traceback_stack(source=source)
  File "<template>", line 1, in top-level template code
  File "/usr/local/lib/python3.11/site-packages/jinja2/sandbox.py", line 326, in getattr
    value = getattr(obj, attribute)
            ^^^^^^^^^^^^^^^^^^^^^^^
  File "/usr/src/homeassistant/homeassistant/helpers/template.py", line 2282, in _fail_with_undefined_error
    raise ex
  File "/usr/src/homeassistant/homeassistant/helpers/template.py", line 2279, in _fail_with_undefined_error
    return super()._fail_with_undefined_error(*args, **kwargs)
           ^^^^^^^^^^^^^^^^^^^^^^^^^^^^^^^^^^^^^^^^^^^^^^^^^^^
jinja2.exceptions.UndefinedError: 'None' has no attribute 'attributes'

The above exception was the direct cause of the following exception:

Traceback (most recent call last):
  File "/usr/src/homeassistant/homeassistant/helpers/template.py", line 695, in async_render_to_info
    render_info._result = self.async_render(
                          ^^^^^^^^^^^^^^^^^^
  File "/usr/src/homeassistant/homeassistant/helpers/template.py", line 571, in async_render
    raise TemplateError(err) from err
homeassistant.exceptions.TemplateError: UndefinedError: 'None' has no attribute 'attributes'
2024-01-01 03:45:35.173 ERROR (MainThread) [homeassistant.helpers.template] Template variable error: 'None' has no attribute 'attributes' when rendering '{{ states.vacuum.hombot.attributes.status }}'
2024-01-01 03:45:35.174 ERROR (MainThread) [homeassistant.components.template.template_entity] TemplateError('UndefinedError: 'None' has no attribute 'attributes'') while processing template 'Template<template=({{ states.vacuum.hombot.attributes.status }}) renders=4>' for attribute '_attr_native_value' in entity 'sensor.hombot_status'
2024-01-01 03:45:35.179 ERROR (MainThread) [homeassistant.helpers.event] Error while processing template: Template<template=({% if states('sensor.medicine_hours_recent')|int > 23 %}
  {% set hours = states('sensor.medicine_hours_recent')|int - 24 %}
{% else %}
  {% set hours = states('sensor.medicine_hours_recent')|int %}
{% endif %}
  {% set minutes = states('sensor.medicine_minutes_recent')|int %}
{{hours|string + ":" + minutes|string }}) renders=2>
Traceback (most recent call last):
  File "/usr/src/homeassistant/homeassistant/helpers/template.py", line 569, in async_render
    render_result = _render_with_context(self.template, compiled, **kwargs)
                    ^^^^^^^^^^^^^^^^^^^^^^^^^^^^^^^^^^^^^^^^^^^^^^^^^^^^^^^
  File "/usr/src/homeassistant/homeassistant/helpers/template.py", line 2247, in _render_with_context
    return template.render(**kwargs)
           ^^^^^^^^^^^^^^^^^^^^^^^^^
  File "/usr/local/lib/python3.11/site-packages/jinja2/environment.py", line 1301, in render
    self.environment.handle_exception()
  File "/usr/local/lib/python3.11/site-packages/jinja2/environment.py", line 936, in handle_exception
    raise rewrite_traceback_stack(source=source)
  File "<template>", line 1, in top-level template code
  File "/usr/src/homeassistant/homeassistant/helpers/template.py", line 1945, in forgiving_int_filter
    raise_no_default("int", value)
  File "/usr/src/homeassistant/homeassistant/helpers/template.py", line 1627, in raise_no_default
    raise ValueError(
ValueError: Template error: int got invalid input 'unknown' when rendering template '{% if states('sensor.medicine_hours_recent')|int > 23 %}
  {% set hours = states('sensor.medicine_hours_recent')|int - 24 %}
{% else %}
  {% set hours = states('sensor.medicine_hours_recent')|int %}
{% endif %}
  {% set minutes = states('sensor.medicine_minutes_recent')|int %}
{{hours|string + ":" + minutes|string }}' but no default was specified

The above exception was the direct cause of the following exception:

Traceback (most recent call last):
  File "/usr/src/homeassistant/homeassistant/helpers/template.py", line 695, in async_render_to_info
    render_info._result = self.async_render(
                          ^^^^^^^^^^^^^^^^^^
  File "/usr/src/homeassistant/homeassistant/helpers/template.py", line 571, in async_render
    raise TemplateError(err) from err
homeassistant.exceptions.TemplateError: ValueError: Template error: int got invalid input 'unknown' when rendering template '{% if states('sensor.medicine_hours_recent')|int > 23 %}
  {% set hours = states('sensor.medicine_hours_recent')|int - 24 %}
{% else %}
  {% set hours = states('sensor.medicine_hours_recent')|int %}
{% endif %}
  {% set minutes = states('sensor.medicine_minutes_recent')|int %}
{{hours|string + ":" + minutes|string }}' but no default was specified
2024-01-01 03:45:35.191 ERROR (MainThread) [homeassistant.components.template.template_entity] TemplateError('ValueError: Template error: int got invalid input 'unknown' when rendering template '{% if states('sensor.medicine_hours_recent')|int > 23 %}
  {% set hours = states('sensor.medicine_hours_recent')|int - 24 %}
{% else %}
  {% set hours = states('sensor.medicine_hours_recent')|int %}
{% endif %}
  {% set minutes = states('sensor.medicine_minutes_recent')|int %}
{{hours|string + ":" + minutes|string }}' but no default was specified') while processing template 'Template<template=({% if states('sensor.medicine_hours_recent')|int > 23 %}
  {% set hours = states('sensor.medicine_hours_recent')|int - 24 %}
{% else %}
  {% set hours = states('sensor.medicine_hours_recent')|int %}
{% endif %}
  {% set minutes = states('sensor.medicine_minutes_recent')|int %}
{{hours|string + ":" + minutes|string }}) renders=4>' for attribute '_attr_native_value' in entity 'sensor.medicine_time_recent'
2024-01-01 03:45:35.328 WARNING (MainThread) [homeassistant.components.homeassistant.triggers.numeric_state] Error initializing 'Living rooms - lights on when blinds close' trigger: In 'numeric_state' condition: entity cover.living_room_blinds state 'closed' cannot be processed as a number
2024-01-01 03:45:35.329 WARNING (MainThread) [homeassistant.components.homeassistant.triggers.numeric_state] Error initializing 'Bedroom - lights off when blinds open' trigger: In 'numeric_state' condition: entity cover.bedroom_blinds state 'closed' cannot be processed as a number
2024-01-01 03:45:39.676 WARNING (MainThread) [custom_components.hacs] You have 'ericpignet/home-assistant-lg_hombot' installed with HACS this repository has been removed from HACS, please consider removing it. Removal reason (Integration is missing a version, and is abandoned.)
2024-01-01 03:45:39.677 WARNING (MainThread) [custom_components.hacs] You have 'ljmerza/ha-our-groceries' installed with HACS this repository has been removed from HACS, please consider removing it. Removal reason (Repository is archived)
2024-01-01 03:45:39.780 WARNING (MainThread) [homeassistant.helpers.template] Template variable warning: 'title' is undefined when rendering '{{ title }}'
2024-01-01 03:45:42.310 ERROR (SyncWorker_3) [homeassistant.components.command_line.utils] Command failed (with return code 1): python3 -c "import requests; import json; import random; dataRequest = requests.get('https://gpsgadget.buienradar.nl/data/raintext?lat=51.83&lon=5.86&c='+str(random.randint(0,999999999999999)) ).text; dataRequest = dataRequest.replace('\r\n',' '); data = '{\"data\":\"'+dataRequest+'\"}';    pri(data);"
2024-01-01 03:45:42.316 WARNING (MainThread) [homeassistant.components.command_line] Empty reply found when expecting JSON data
2024-01-01 03:45:48.175 WARNING (Recorder) [homeassistant.components.sensor.recorder] The unit of sensor.openweathermap_rain (mm/h) cannot be converted to the unit of previously compiled statistics (mm). Generation of long term statistics will be suppressed unless the unit changes back to mm or a compatible unit. Go to https://my.home-assistant.io/redirect/developer_statistics to fix this
2024-01-01 03:45:48.175 WARNING (Recorder) [homeassistant.components.sensor.recorder] The unit of sensor.openweathermap_snow (mm/h) cannot be converted to the unit of previously compiled statistics (mm). Generation of long term statistics will be suppressed unless the unit changes back to mm or a compatible unit. Go to https://my.home-assistant.io/redirect/developer_statistics to fix this
2024-01-01 03:45:48.176 WARNING (Recorder) [homeassistant.components.sensor.recorder] The unit of sensor.home_precipitation (mm/h) cannot be converted to the unit of previously compiled statistics (mm). Generation of long term statistics will be suppressed unless the unit changes back to mm or a compatible unit. Go to https://my.home-assistant.io/redirect/developer_statistics to fix this
2024-01-01 03:46:09.979 WARNING (MainThread) [homeassistant.helpers.template] Template variable warning: 'title' is undefined when rendering '{{ title }}'
2024-01-01 03:46:09.996 WARNING (MainThread) [homeassistant.helpers.template] Template variable warning: 'title' is undefined when rendering '{{ title }}'
2024-01-01 03:49:09.961 WARNING (MainThread) [homeassistant.helpers.script] Error in 'if[0]' evaluation: In 'numeric_state':
  In 'numeric_state' condition: unknown entity sensor.humidity_11
2024-01-01 03:49:28.052 ERROR (MainThread) [homeassistant.components.shell_command] Error running command: `/bin/bash pushupdates.sh`, return code: 1
NoneType: None
2024-01-01 03:49:42.168 ERROR (SyncWorker_5) [homeassistant.components.command_line.utils] Command failed (with return code 1): python3 -c "import requests; import json; import random; dataRequest = requests.get('https://gpsgadget.buienradar.nl/data/raintext?lat=51.83&lon=5.86&c='+str(random.randint(0,999999999999999)) ).text; dataRequest = dataRequest.replace('\r\n',' '); data = '{\"data\":\"'+dataRequest+'\"}';    pri(data);"
2024-01-01 03:49:42.170 WARNING (MainThread) [homeassistant.components.command_line] Empty reply found when expecting JSON data
2024-01-01 03:50:40.769 ERROR (MainThread) [homeassistant.components.shell_command] Error running command: `/bin/bash pushupdates.sh`, return code: 1
NoneType: None
2024-01-01 03:51:06.569 WARNING (Thread-8) [pychromecast.socket_client] [Bedroom(192.168.69.236):8009] Heartbeat timeout, resetting connection
2024-01-01 03:51:36.575 ERROR (Thread-8) [pychromecast.socket_client] [Bedroom(192.168.69.236):8009] Failed to connect to service ServiceInfo(type='host', data=('192.168.69.236', 8009)), retrying in 5.0s
2024-01-01 03:52:09.962 ERROR (MainThread) [homeassistant.components.shell_command] Error running command: `/bin/bash pushupdates.sh`, return code: 1
NoneType: None
2024-01-01 03:53:42.073 ERROR (SyncWorker_6) [homeassistant.components.command_line.utils] Command failed (with return code 1): python3 -c "import requests; import json; import random; dataRequest = requests.get('https://gpsgadget.buienradar.nl/data/raintext?lat=51.83&lon=5.86&c='+str(random.randint(0,999999999999999)) ).text; dataRequest = dataRequest.replace('\r\n',' '); data = '{\"data\":\"'+dataRequest+'\"}';    pri(data);"
2024-01-01 03:53:42.074 WARNING (MainThread) [homeassistant.components.command_line] Empty reply found when expecting JSON data
2024-01-01 03:57:14.910 ERROR (MainThread) [homeassistant.components.shell_command] Error running command: `/bin/bash pushupdates.sh`, return code: 1
NoneType: None
2024-01-01 03:57:42.057 ERROR (SyncWorker_4) [homeassistant.components.command_line.utils] Command failed (with return code 1): python3 -c "import requests; import json; import random; dataRequest = requests.get('https://gpsgadget.buienradar.nl/data/raintext?lat=51.83&lon=5.86&c='+str(random.randint(0,999999999999999)) ).text; dataRequest = dataRequest.replace('\r\n',' '); data = '{\"data\":\"'+dataRequest+'\"}';    pri(data);"
2024-01-01 03:57:42.058 WARNING (MainThread) [homeassistant.components.command_line] Empty reply found when expecting JSON data
