2023-11-03 17:31:03.845 WARNING (SyncWorker_0) [homeassistant.loader] We found a custom integration breaking_changes which has not been tested by Home Assistant. This component might cause stability problems, be sure to disable it if you experience issues with Home Assistant
2023-11-03 17:31:03.850 WARNING (SyncWorker_0) [homeassistant.loader] We found a custom integration plex_recently_added which has not been tested by Home Assistant. This component might cause stability problems, be sure to disable it if you experience issues with Home Assistant
2023-11-03 17:31:03.853 WARNING (SyncWorker_0) [homeassistant.loader] We found a custom integration manish which has not been tested by Home Assistant. This component might cause stability problems, be sure to disable it if you experience issues with Home Assistant
2023-11-03 17:31:03.856 WARNING (SyncWorker_0) [homeassistant.loader] We found a custom integration plex_assistant which has not been tested by Home Assistant. This component might cause stability problems, be sure to disable it if you experience issues with Home Assistant
2023-11-03 17:31:03.859 WARNING (SyncWorker_0) [homeassistant.loader] We found a custom integration anniversaries which has not been tested by Home Assistant. This component might cause stability problems, be sure to disable it if you experience issues with Home Assistant
2023-11-03 17:31:03.861 WARNING (SyncWorker_0) [homeassistant.loader] We found a custom integration ourgroceries which has not been tested by Home Assistant. This component might cause stability problems, be sure to disable it if you experience issues with Home Assistant
2023-11-03 17:31:03.865 WARNING (SyncWorker_0) [homeassistant.loader] We found a custom integration average which has not been tested by Home Assistant. This component might cause stability problems, be sure to disable it if you experience issues with Home Assistant
2023-11-03 17:31:03.868 WARNING (SyncWorker_0) [homeassistant.loader] We found a custom integration afvalinfo which has not been tested by Home Assistant. This component might cause stability problems, be sure to disable it if you experience issues with Home Assistant
2023-11-03 17:31:03.871 WARNING (SyncWorker_0) [homeassistant.loader] We found a custom integration car_wash which has not been tested by Home Assistant. This component might cause stability problems, be sure to disable it if you experience issues with Home Assistant
2023-11-03 17:31:03.873 WARNING (SyncWorker_0) [homeassistant.loader] We found a custom integration saver which has not been tested by Home Assistant. This component might cause stability problems, be sure to disable it if you experience issues with Home Assistant
2023-11-03 17:31:03.875 WARNING (SyncWorker_0) [homeassistant.loader] We found a custom integration buienalarm which has not been tested by Home Assistant. This component might cause stability problems, be sure to disable it if you experience issues with Home Assistant
2023-11-03 17:31:03.878 WARNING (SyncWorker_0) [homeassistant.loader] We found a custom integration hacs which has not been tested by Home Assistant. This component might cause stability problems, be sure to disable it if you experience issues with Home Assistant
2023-11-03 17:31:03.880 WARNING (SyncWorker_0) [homeassistant.loader] We found a custom integration favicon which has not been tested by Home Assistant. This component might cause stability problems, be sure to disable it if you experience issues with Home Assistant
2023-11-03 17:31:03.882 WARNING (SyncWorker_0) [homeassistant.loader] We found a custom integration temperature_feels_like which has not been tested by Home Assistant. This component might cause stability problems, be sure to disable it if you experience issues with Home Assistant
2023-11-03 17:31:03.885 WARNING (SyncWorker_0) [homeassistant.loader] We found a custom integration illuminance which has not been tested by Home Assistant. This component might cause stability problems, be sure to disable it if you experience issues with Home Assistant
2023-11-03 17:31:03.887 WARNING (SyncWorker_0) [homeassistant.loader] We found a custom integration hpprinter which has not been tested by Home Assistant. This component might cause stability problems, be sure to disable it if you experience issues with Home Assistant
2023-11-03 17:31:03.889 WARNING (SyncWorker_0) [homeassistant.loader] We found a custom integration fontawesome which has not been tested by Home Assistant. This component might cause stability problems, be sure to disable it if you experience issues with Home Assistant
2023-11-03 17:31:03.891 WARNING (SyncWorker_0) [homeassistant.loader] We found a custom integration pyscript which has not been tested by Home Assistant. This component might cause stability problems, be sure to disable it if you experience issues with Home Assistant
2023-11-03 17:31:03.894 WARNING (SyncWorker_0) [homeassistant.loader] We found a custom integration simpleicons which has not been tested by Home Assistant. This component might cause stability problems, be sure to disable it if you experience issues with Home Assistant
2023-11-03 17:31:03.896 WARNING (SyncWorker_0) [homeassistant.loader] We found a custom integration google_home which has not been tested by Home Assistant. This component might cause stability problems, be sure to disable it if you experience issues with Home Assistant
2023-11-03 17:31:03.898 WARNING (SyncWorker_0) [homeassistant.loader] We found a custom integration afvalbeheer which has not been tested by Home Assistant. This component might cause stability problems, be sure to disable it if you experience issues with Home Assistant
2023-11-03 17:31:03.900 WARNING (SyncWorker_0) [homeassistant.loader] We found a custom integration worlds_air_quality_index which has not been tested by Home Assistant. This component might cause stability problems, be sure to disable it if you experience issues with Home Assistant
2023-11-03 17:31:03.902 WARNING (SyncWorker_0) [homeassistant.loader] We found a custom integration knmi which has not been tested by Home Assistant. This component might cause stability problems, be sure to disable it if you experience issues with Home Assistant
2023-11-03 17:31:03.904 WARNING (SyncWorker_0) [homeassistant.loader] We found a custom integration google_photos which has not been tested by Home Assistant. This component might cause stability problems, be sure to disable it if you experience issues with Home Assistant
2023-11-03 17:31:03.907 WARNING (SyncWorker_0) [homeassistant.loader] We found a custom integration n26 which has not been tested by Home Assistant. This component might cause stability problems, be sure to disable it if you experience issues with Home Assistant
2023-11-03 17:31:03.907 ERROR (SyncWorker_0) [homeassistant.loader] The custom integration 'n26' does not have a version key in the manifest file and was blocked from loading. See https://developers.home-assistant.io/blog/2021/01/29/custom-integration-changes#versions for more details
2023-11-03 17:31:03.910 WARNING (SyncWorker_0) [homeassistant.loader] We found a custom integration whatspie which has not been tested by Home Assistant. This component might cause stability problems, be sure to disable it if you experience issues with Home Assistant
2023-11-03 17:31:03.912 WARNING (SyncWorker_0) [homeassistant.loader] We found a custom integration lg_hombot which has not been tested by Home Assistant. This component might cause stability problems, be sure to disable it if you experience issues with Home Assistant
2023-11-03 17:31:03.914 WARNING (SyncWorker_0) [homeassistant.loader] We found a custom integration pollenprognos which has not been tested by Home Assistant. This component might cause stability problems, be sure to disable it if you experience issues with Home Assistant
2023-11-03 17:31:03.915 WARNING (SyncWorker_0) [homeassistant.loader] We found a custom integration jokes which has not been tested by Home Assistant. This component might cause stability problems, be sure to disable it if you experience issues with Home Assistant
2023-11-03 17:31:03.917 WARNING (SyncWorker_0) [homeassistant.loader] We found a custom integration auto_backup which has not been tested by Home Assistant. This component might cause stability problems, be sure to disable it if you experience issues with Home Assistant
2023-11-03 17:31:03.919 WARNING (SyncWorker_0) [homeassistant.loader] We found a custom integration spotcast which has not been tested by Home Assistant. This component might cause stability problems, be sure to disable it if you experience issues with Home Assistant
2023-11-03 17:31:22.402 ERROR (MainThread) [homeassistant.helpers.template] Template variable error: 'None' has no attribute 'attributes' when rendering '{{ states.vacuum.hombot.attributes.battery_icon }}'
2023-11-03 17:31:22.572 ERROR (SyncWorker_6) [glocaltokens.client] [!] Could not get access token.
2023-11-03 17:31:27.658 ERROR (SyncWorker_7) [homeassistant.components.command_line.utils] Command failed (with return code 1): python3 -c "import requests; import json; import random; dataRequest = requests.get('https://gpsgadget.buienradar.nl/data/raintext?lat=51.83&lon=5.86&c='+str(random.randint(0,999999999999999)) ).text; dataRequest = dataRequest.replace('\r\n',' '); data = '{\"data\":\"'+dataRequest+'\"}';    pri(data);"
2023-11-03 17:31:27.660 WARNING (MainThread) [homeassistant.components.command_line] Empty reply found when expecting JSON data
2023-11-03 17:31:27.664 WARNING (MainThread) [homeassistant.helpers.template] Template variable warning: 'None' has no attribute 'last_changed' when rendering 'last_changed: {{states.sensor.neerslag_buienalarm_regen_data.last_changed}}'
2023-11-03 17:32:01.950 WARNING (SyncWorker_0) [py.warnings] /usr/local/lib/python3.11/site-packages/urllib3/connectionpool.py:1061: InsecureRequestWarning: Unverified HTTPS request is being made to host '192.168.69.103'. Adding certificate verification is strongly advised. See: https://urllib3.readthedocs.io/en/1.26.x/advanced-usage.html#ssl-warnings
  warnings.warn(

2023-11-03 17:32:01.964 WARNING (SyncWorker_0) [py.warnings] /usr/local/lib/python3.11/site-packages/urllib3/connectionpool.py:1061: InsecureRequestWarning: Unverified HTTPS request is being made to host '192.168.69.103'. Adding certificate verification is strongly advised. See: https://urllib3.readthedocs.io/en/1.26.x/advanced-usage.html#ssl-warnings
  warnings.warn(

2023-11-03 17:32:02.589 WARNING (SyncWorker_6) [py.warnings] /usr/local/lib/python3.11/site-packages/urllib3/connectionpool.py:1061: InsecureRequestWarning: Unverified HTTPS request is being made to host '192.168.69.103'. Adding certificate verification is strongly advised. See: https://urllib3.readthedocs.io/en/1.26.x/advanced-usage.html#ssl-warnings
  warnings.warn(

2023-11-03 17:32:02.598 WARNING (SyncWorker_6) [py.warnings] /usr/local/lib/python3.11/site-packages/urllib3/connectionpool.py:1061: InsecureRequestWarning: Unverified HTTPS request is being made to host '192.168.69.103'. Adding certificate verification is strongly advised. See: https://urllib3.readthedocs.io/en/1.26.x/advanced-usage.html#ssl-warnings
  warnings.warn(

2023-11-03 17:32:02.612 WARNING (SyncWorker_6) [py.warnings] /usr/local/lib/python3.11/site-packages/urllib3/connectionpool.py:1061: InsecureRequestWarning: Unverified HTTPS request is being made to host '192.168.69.103'. Adding certificate verification is strongly advised. See: https://urllib3.readthedocs.io/en/1.26.x/advanced-usage.html#ssl-warnings
  warnings.warn(

2023-11-03 17:32:02.631 WARNING (SyncWorker_6) [py.warnings] /usr/local/lib/python3.11/site-packages/urllib3/connectionpool.py:1061: InsecureRequestWarning: Unverified HTTPS request is being made to host '192.168.69.103'. Adding certificate verification is strongly advised. See: https://urllib3.readthedocs.io/en/1.26.x/advanced-usage.html#ssl-warnings
  warnings.warn(

2023-11-03 17:32:02.646 WARNING (SyncWorker_6) [py.warnings] /usr/local/lib/python3.11/site-packages/urllib3/connectionpool.py:1061: InsecureRequestWarning: Unverified HTTPS request is being made to host '192.168.69.103'. Adding certificate verification is strongly advised. See: https://urllib3.readthedocs.io/en/1.26.x/advanced-usage.html#ssl-warnings
  warnings.warn(

2023-11-03 17:32:02.682 WARNING (SyncWorker_6) [py.warnings] /usr/local/lib/python3.11/site-packages/urllib3/connectionpool.py:1061: InsecureRequestWarning: Unverified HTTPS request is being made to host '192.168.69.103'. Adding certificate verification is strongly advised. See: https://urllib3.readthedocs.io/en/1.26.x/advanced-usage.html#ssl-warnings
  warnings.warn(

2023-11-03 17:32:02.843 WARNING (SyncWorker_6) [py.warnings] /usr/local/lib/python3.11/site-packages/urllib3/connectionpool.py:1061: InsecureRequestWarning: Unverified HTTPS request is being made to host '192.168.69.103'. Adding certificate verification is strongly advised. See: https://urllib3.readthedocs.io/en/1.26.x/advanced-usage.html#ssl-warnings
  warnings.warn(

2023-11-03 17:32:02.864 WARNING (SyncWorker_6) [py.warnings] /usr/local/lib/python3.11/site-packages/urllib3/connectionpool.py:1061: InsecureRequestWarning: Unverified HTTPS request is being made to host '192.168.69.103'. Adding certificate verification is strongly advised. See: https://urllib3.readthedocs.io/en/1.26.x/advanced-usage.html#ssl-warnings
  warnings.warn(

2023-11-03 17:32:02.875 WARNING (SyncWorker_6) [py.warnings] /usr/local/lib/python3.11/site-packages/urllib3/connectionpool.py:1061: InsecureRequestWarning: Unverified HTTPS request is being made to host '192.168.69.103'. Adding certificate verification is strongly advised. See: https://urllib3.readthedocs.io/en/1.26.x/advanced-usage.html#ssl-warnings
  warnings.warn(

2023-11-03 17:32:03.086 WARNING (SyncWorker_6) [py.warnings] /usr/local/lib/python3.11/site-packages/urllib3/connectionpool.py:1061: InsecureRequestWarning: Unverified HTTPS request is being made to host '192.168.69.103'. Adding certificate verification is strongly advised. See: https://urllib3.readthedocs.io/en/1.26.x/advanced-usage.html#ssl-warnings
  warnings.warn(

2023-11-03 17:32:03.803 ERROR (MainThread) [homeassistant.helpers.integration_platform] Error processing platform plex_assistant.intent
Traceback (most recent call last):
  File "/usr/src/homeassistant/homeassistant/helpers/integration_platform.py", line 61, in _async_process_single_integration_platform_component
    await integration_platform.process_platform(hass, component_name, platform)
  File "/usr/src/homeassistant/homeassistant/components/intent/__init__.py", line 225, in _async_process_intent
    await platform.async_setup_intents(hass)
  File "/config/custom_components/plex_assistant/intent.py", line 9, in async_setup_intents
    hass.components.conversation.async_register(
    ^^^^^^^^^^^^^^^^^^^^^^^^^^^^^^^^^^^^^^^^^^^
  File "/usr/src/homeassistant/homeassistant/loader.py", line 1071, in __getattr__
    value = getattr(self._module, attr)
            ^^^^^^^^^^^^^^^^^^^^^^^^^^^
AttributeError: module 'homeassistant.components.conversation' has no attribute 'async_register'
2023-11-03 17:32:05.509 WARNING (SyncWorker_8) [py.warnings] /usr/local/lib/python3.11/site-packages/urllib3/connectionpool.py:1061: InsecureRequestWarning: Unverified HTTPS request is being made to host '192.168.69.103'. Adding certificate verification is strongly advised. See: https://urllib3.readthedocs.io/en/1.26.x/advanced-usage.html#ssl-warnings
  warnings.warn(

2023-11-03 17:32:05.561 WARNING (SyncWorker_6) [py.warnings] /usr/local/lib/python3.11/site-packages/urllib3/connectionpool.py:1061: InsecureRequestWarning: Unverified HTTPS request is being made to host '192.168.69.103'. Adding certificate verification is strongly advised. See: https://urllib3.readthedocs.io/en/1.26.x/advanced-usage.html#ssl-warnings
  warnings.warn(

2023-11-03 17:32:05.614 WARNING (SyncWorker_0) [py.warnings] /usr/local/lib/python3.11/site-packages/urllib3/connectionpool.py:1061: InsecureRequestWarning: Unverified HTTPS request is being made to host '192.168.69.103'. Adding certificate verification is strongly advised. See: https://urllib3.readthedocs.io/en/1.26.x/advanced-usage.html#ssl-warnings
  warnings.warn(

2023-11-03 17:32:05.706 WARNING (SyncWorker_6) [py.warnings] /usr/local/lib/python3.11/site-packages/urllib3/connectionpool.py:1061: InsecureRequestWarning: Unverified HTTPS request is being made to host '192.168.69.103'. Adding certificate verification is strongly advised. See: https://urllib3.readthedocs.io/en/1.26.x/advanced-usage.html#ssl-warnings
  warnings.warn(

2023-11-03 17:32:06.845 WARNING (SyncWorker_7) [py.warnings] /usr/local/lib/python3.11/site-packages/urllib3/connectionpool.py:1061: InsecureRequestWarning: Unverified HTTPS request is being made to host '192.168.69.103'. Adding certificate verification is strongly advised. See: https://urllib3.readthedocs.io/en/1.26.x/advanced-usage.html#ssl-warnings
  warnings.warn(

2023-11-03 17:32:06.851 WARNING (SyncWorker_7) [py.warnings] /usr/local/lib/python3.11/site-packages/urllib3/connectionpool.py:1061: InsecureRequestWarning: Unverified HTTPS request is being made to host '192.168.69.103'. Adding certificate verification is strongly advised. See: https://urllib3.readthedocs.io/en/1.26.x/advanced-usage.html#ssl-warnings
  warnings.warn(

2023-11-03 17:32:12.305 ERROR (MainThread) [homeassistant.components.hassio.handler] /ingress/validate_session return code 401
2023-11-03 17:32:12.306 ERROR (MainThread) [homeassistant.components.hassio] Failed to to call /ingress/validate_session - 
2023-11-03 17:32:22.319 WARNING (MainThread) [homeassistant.bootstrap] Waiting on integrations to complete setup: mqtt
2023-11-03 17:32:36.079 ERROR (MainThread) [homeassistant.helpers.event] Error while processing template: Template<template=({{ (states.sensor.desk_light_button_device_temperature.state | float - 8 ) | round(0) }}) renders=2>
Traceback (most recent call last):
  File "/usr/src/homeassistant/homeassistant/helpers/template.py", line 1925, in forgiving_float_filter
    return float(value)
           ^^^^^^^^^^^^
ValueError: could not convert string to float: 'unavailable'

During handling of the above exception, another exception occurred:

Traceback (most recent call last):
  File "/usr/src/homeassistant/homeassistant/helpers/template.py", line 568, in async_render
    render_result = _render_with_context(self.template, compiled, **kwargs)
                    ^^^^^^^^^^^^^^^^^^^^^^^^^^^^^^^^^^^^^^^^^^^^^^^^^^^^^^^
  File "/usr/src/homeassistant/homeassistant/helpers/template.py", line 2231, in _render_with_context
    return template.render(**kwargs)
           ^^^^^^^^^^^^^^^^^^^^^^^^^
  File "/usr/local/lib/python3.11/site-packages/jinja2/environment.py", line 1301, in render
    self.environment.handle_exception()
  File "/usr/local/lib/python3.11/site-packages/jinja2/environment.py", line 936, in handle_exception
    raise rewrite_traceback_stack(source=source)
  File "<template>", line 1, in top-level template code
  File "/usr/src/homeassistant/homeassistant/helpers/template.py", line 1928, in forgiving_float_filter
    raise_no_default("float", value)
  File "/usr/src/homeassistant/homeassistant/helpers/template.py", line 1626, in raise_no_default
    raise ValueError(
ValueError: Template error: float got invalid input 'unavailable' when rendering template '{{ (states.sensor.desk_light_button_device_temperature.state | float - 8 ) | round(0) }}' but no default was specified

The above exception was the direct cause of the following exception:

Traceback (most recent call last):
  File "/usr/src/homeassistant/homeassistant/helpers/template.py", line 694, in async_render_to_info
    render_info._result = self.async_render(
                          ^^^^^^^^^^^^^^^^^^
  File "/usr/src/homeassistant/homeassistant/helpers/template.py", line 570, in async_render
    raise TemplateError(err) from err
homeassistant.exceptions.TemplateError: ValueError: Template error: float got invalid input 'unavailable' when rendering template '{{ (states.sensor.desk_light_button_device_temperature.state | float - 8 ) | round(0) }}' but no default was specified
2023-11-03 17:32:36.098 ERROR (MainThread) [homeassistant.components.template.template_entity] TemplateError('ValueError: Template error: float got invalid input 'unavailable' when rendering template '{{ (states.sensor.desk_light_button_device_temperature.state | float - 8 ) | round(0) }}' but no default was specified') while processing template 'Template<template=({{ (states.sensor.desk_light_button_device_temperature.state | float - 8 ) | round(0) }}) renders=4>' for attribute '_attr_native_value' in entity 'sensor.desk_temp_adj'
2023-11-03 17:32:36.104 ERROR (MainThread) [homeassistant.helpers.event] Error while processing template: Template<template=({{ (states.sensor.front_door_sensor_device_temperature.state | float - 3 ) | round(0) }}) renders=2>
Traceback (most recent call last):
  File "/usr/src/homeassistant/homeassistant/helpers/template.py", line 1925, in forgiving_float_filter
    return float(value)
           ^^^^^^^^^^^^
ValueError: could not convert string to float: 'unavailable'

During handling of the above exception, another exception occurred:

Traceback (most recent call last):
  File "/usr/src/homeassistant/homeassistant/helpers/template.py", line 568, in async_render
    render_result = _render_with_context(self.template, compiled, **kwargs)
                    ^^^^^^^^^^^^^^^^^^^^^^^^^^^^^^^^^^^^^^^^^^^^^^^^^^^^^^^
  File "/usr/src/homeassistant/homeassistant/helpers/template.py", line 2231, in _render_with_context
    return template.render(**kwargs)
           ^^^^^^^^^^^^^^^^^^^^^^^^^
  File "/usr/local/lib/python3.11/site-packages/jinja2/environment.py", line 1301, in render
    self.environment.handle_exception()
  File "/usr/local/lib/python3.11/site-packages/jinja2/environment.py", line 936, in handle_exception
    raise rewrite_traceback_stack(source=source)
  File "<template>", line 1, in top-level template code
  File "/usr/src/homeassistant/homeassistant/helpers/template.py", line 1928, in forgiving_float_filter
    raise_no_default("float", value)
  File "/usr/src/homeassistant/homeassistant/helpers/template.py", line 1626, in raise_no_default
    raise ValueError(
ValueError: Template error: float got invalid input 'unavailable' when rendering template '{{ (states.sensor.front_door_sensor_device_temperature.state | float - 3 ) | round(0) }}' but no default was specified

The above exception was the direct cause of the following exception:

Traceback (most recent call last):
  File "/usr/src/homeassistant/homeassistant/helpers/template.py", line 694, in async_render_to_info
    render_info._result = self.async_render(
                          ^^^^^^^^^^^^^^^^^^
  File "/usr/src/homeassistant/homeassistant/helpers/template.py", line 570, in async_render
    raise TemplateError(err) from err
homeassistant.exceptions.TemplateError: ValueError: Template error: float got invalid input 'unavailable' when rendering template '{{ (states.sensor.front_door_sensor_device_temperature.state | float - 3 ) | round(0) }}' but no default was specified
2023-11-03 17:32:36.113 ERROR (MainThread) [homeassistant.components.template.template_entity] TemplateError('ValueError: Template error: float got invalid input 'unavailable' when rendering template '{{ (states.sensor.front_door_sensor_device_temperature.state | float - 3 ) | round(0) }}' but no default was specified') while processing template 'Template<template=({{ (states.sensor.front_door_sensor_device_temperature.state | float - 3 ) | round(0) }}) renders=4>' for attribute '_attr_native_value' in entity 'sensor.front_door_sensor_device_temperature_adj'
2023-11-03 17:32:36.115 ERROR (MainThread) [homeassistant.helpers.event] Error while processing template: Template<template=({{ (states.sensor.living_room_window_sensor_device_temperature.state | float - 4 ) | round(0) }}) renders=2>
Traceback (most recent call last):
  File "/usr/src/homeassistant/homeassistant/helpers/template.py", line 1925, in forgiving_float_filter
    return float(value)
           ^^^^^^^^^^^^
ValueError: could not convert string to float: 'unavailable'

During handling of the above exception, another exception occurred:

Traceback (most recent call last):
  File "/usr/src/homeassistant/homeassistant/helpers/template.py", line 568, in async_render
    render_result = _render_with_context(self.template, compiled, **kwargs)
                    ^^^^^^^^^^^^^^^^^^^^^^^^^^^^^^^^^^^^^^^^^^^^^^^^^^^^^^^
  File "/usr/src/homeassistant/homeassistant/helpers/template.py", line 2231, in _render_with_context
    return template.render(**kwargs)
           ^^^^^^^^^^^^^^^^^^^^^^^^^
  File "/usr/local/lib/python3.11/site-packages/jinja2/environment.py", line 1301, in render
    self.environment.handle_exception()
  File "/usr/local/lib/python3.11/site-packages/jinja2/environment.py", line 936, in handle_exception
    raise rewrite_traceback_stack(source=source)
  File "<template>", line 1, in top-level template code
  File "/usr/src/homeassistant/homeassistant/helpers/template.py", line 1928, in forgiving_float_filter
    raise_no_default("float", value)
  File "/usr/src/homeassistant/homeassistant/helpers/template.py", line 1626, in raise_no_default
    raise ValueError(
ValueError: Template error: float got invalid input 'unavailable' when rendering template '{{ (states.sensor.living_room_window_sensor_device_temperature.state | float - 4 ) | round(0) }}' but no default was specified

The above exception was the direct cause of the following exception:

Traceback (most recent call last):
  File "/usr/src/homeassistant/homeassistant/helpers/template.py", line 694, in async_render_to_info
    render_info._result = self.async_render(
                          ^^^^^^^^^^^^^^^^^^
  File "/usr/src/homeassistant/homeassistant/helpers/template.py", line 570, in async_render
    raise TemplateError(err) from err
homeassistant.exceptions.TemplateError: ValueError: Template error: float got invalid input 'unavailable' when rendering template '{{ (states.sensor.living_room_window_sensor_device_temperature.state | float - 4 ) | round(0) }}' but no default was specified
2023-11-03 17:32:36.126 ERROR (MainThread) [homeassistant.components.template.template_entity] TemplateError('ValueError: Template error: float got invalid input 'unavailable' when rendering template '{{ (states.sensor.living_room_window_sensor_device_temperature.state | float - 4 ) | round(0) }}' but no default was specified') while processing template 'Template<template=({{ (states.sensor.living_room_window_sensor_device_temperature.state | float - 4 ) | round(0) }}) renders=4>' for attribute '_attr_native_value' in entity 'sensor.living_room_window_sensor_device_temperature_adj'
2023-11-03 17:32:36.127 ERROR (MainThread) [homeassistant.helpers.template] Template variable error: 'None' has no attribute 'attributes' when rendering '{{ states.vacuum.hombot.attributes.battery_level }}'
2023-11-03 17:32:36.128 ERROR (MainThread) [homeassistant.helpers.event] Error while processing template: Template<template=({{ states.vacuum.hombot.attributes.battery_level }}) renders=2>
Traceback (most recent call last):
  File "/usr/src/homeassistant/homeassistant/helpers/template.py", line 568, in async_render
    render_result = _render_with_context(self.template, compiled, **kwargs)
                    ^^^^^^^^^^^^^^^^^^^^^^^^^^^^^^^^^^^^^^^^^^^^^^^^^^^^^^^
  File "/usr/src/homeassistant/homeassistant/helpers/template.py", line 2231, in _render_with_context
    return template.render(**kwargs)
           ^^^^^^^^^^^^^^^^^^^^^^^^^
  File "/usr/local/lib/python3.11/site-packages/jinja2/environment.py", line 1301, in render
    self.environment.handle_exception()
  File "/usr/local/lib/python3.11/site-packages/jinja2/environment.py", line 936, in handle_exception
    raise rewrite_traceback_stack(source=source)
  File "<template>", line 1, in top-level template code
  File "/usr/local/lib/python3.11/site-packages/jinja2/sandbox.py", line 326, in getattr
    value = getattr(obj, attribute)
            ^^^^^^^^^^^^^^^^^^^^^^^
  File "/usr/src/homeassistant/homeassistant/helpers/template.py", line 2266, in _fail_with_undefined_error
    raise ex
  File "/usr/src/homeassistant/homeassistant/helpers/template.py", line 2263, in _fail_with_undefined_error
    return super()._fail_with_undefined_error(*args, **kwargs)
           ^^^^^^^^^^^^^^^^^^^^^^^^^^^^^^^^^^^^^^^^^^^^^^^^^^^
jinja2.exceptions.UndefinedError: 'None' has no attribute 'attributes'

The above exception was the direct cause of the following exception:

Traceback (most recent call last):
  File "/usr/src/homeassistant/homeassistant/helpers/template.py", line 694, in async_render_to_info
    render_info._result = self.async_render(
                          ^^^^^^^^^^^^^^^^^^
  File "/usr/src/homeassistant/homeassistant/helpers/template.py", line 570, in async_render
    raise TemplateError(err) from err
homeassistant.exceptions.TemplateError: UndefinedError: 'None' has no attribute 'attributes'
2023-11-03 17:32:36.138 ERROR (MainThread) [homeassistant.helpers.template] Template variable error: 'None' has no attribute 'attributes' when rendering '{{ states.vacuum.hombot.attributes.battery_icon }}'
2023-11-03 17:32:36.139 ERROR (MainThread) [homeassistant.helpers.event] Error while processing template: Template<template=({{ states.vacuum.hombot.attributes.battery_icon }}) renders=3>
Traceback (most recent call last):
  File "/usr/src/homeassistant/homeassistant/helpers/template.py", line 568, in async_render
    render_result = _render_with_context(self.template, compiled, **kwargs)
                    ^^^^^^^^^^^^^^^^^^^^^^^^^^^^^^^^^^^^^^^^^^^^^^^^^^^^^^^
  File "/usr/src/homeassistant/homeassistant/helpers/template.py", line 2231, in _render_with_context
    return template.render(**kwargs)
           ^^^^^^^^^^^^^^^^^^^^^^^^^
  File "/usr/local/lib/python3.11/site-packages/jinja2/environment.py", line 1301, in render
    self.environment.handle_exception()
  File "/usr/local/lib/python3.11/site-packages/jinja2/environment.py", line 936, in handle_exception
    raise rewrite_traceback_stack(source=source)
  File "<template>", line 1, in top-level template code
  File "/usr/local/lib/python3.11/site-packages/jinja2/sandbox.py", line 326, in getattr
    value = getattr(obj, attribute)
            ^^^^^^^^^^^^^^^^^^^^^^^
  File "/usr/src/homeassistant/homeassistant/helpers/template.py", line 2266, in _fail_with_undefined_error
    raise ex
  File "/usr/src/homeassistant/homeassistant/helpers/template.py", line 2263, in _fail_with_undefined_error
    return super()._fail_with_undefined_error(*args, **kwargs)
           ^^^^^^^^^^^^^^^^^^^^^^^^^^^^^^^^^^^^^^^^^^^^^^^^^^^
jinja2.exceptions.UndefinedError: 'None' has no attribute 'attributes'

The above exception was the direct cause of the following exception:

Traceback (most recent call last):
  File "/usr/src/homeassistant/homeassistant/helpers/template.py", line 694, in async_render_to_info
    render_info._result = self.async_render(
                          ^^^^^^^^^^^^^^^^^^
  File "/usr/src/homeassistant/homeassistant/helpers/template.py", line 570, in async_render
    raise TemplateError(err) from err
homeassistant.exceptions.TemplateError: UndefinedError: 'None' has no attribute 'attributes'
2023-11-03 17:32:36.147 ERROR (MainThread) [homeassistant.helpers.template] Template variable error: 'None' has no attribute 'attributes' when rendering '{{ states.vacuum.hombot.attributes.battery_level }}'
2023-11-03 17:32:36.148 ERROR (MainThread) [homeassistant.helpers.template] Template variable error: 'None' has no attribute 'attributes' when rendering '{{ states.vacuum.hombot.attributes.battery_icon }}'
2023-11-03 17:32:36.148 ERROR (MainThread) [homeassistant.components.template.template_entity] TemplateError('UndefinedError: 'None' has no attribute 'attributes'') while processing template 'Template<template=({{ states.vacuum.hombot.attributes.battery_level }}) renders=4>' for attribute '_attr_native_value' in entity 'sensor.hombot_battery'
2023-11-03 17:32:36.149 ERROR (MainThread) [homeassistant.components.template.template_entity] TemplateError('UndefinedError: 'None' has no attribute 'attributes'') while processing template 'Template<template=({{ states.vacuum.hombot.attributes.battery_icon }}) renders=5>' for attribute '_attr_icon' in entity 'sensor.hombot_battery'
2023-11-03 17:32:36.150 ERROR (MainThread) [homeassistant.helpers.template] Template variable error: 'None' has no attribute 'attributes' when rendering '{{ states.vacuum.hombot.attributes.status }}'
2023-11-03 17:32:36.150 ERROR (MainThread) [homeassistant.helpers.event] Error while processing template: Template<template=({{ states.vacuum.hombot.attributes.status }}) renders=2>
Traceback (most recent call last):
  File "/usr/src/homeassistant/homeassistant/helpers/template.py", line 568, in async_render
    render_result = _render_with_context(self.template, compiled, **kwargs)
                    ^^^^^^^^^^^^^^^^^^^^^^^^^^^^^^^^^^^^^^^^^^^^^^^^^^^^^^^
  File "/usr/src/homeassistant/homeassistant/helpers/template.py", line 2231, in _render_with_context
    return template.render(**kwargs)
           ^^^^^^^^^^^^^^^^^^^^^^^^^
  File "/usr/local/lib/python3.11/site-packages/jinja2/environment.py", line 1301, in render
    self.environment.handle_exception()
  File "/usr/local/lib/python3.11/site-packages/jinja2/environment.py", line 936, in handle_exception
    raise rewrite_traceback_stack(source=source)
  File "<template>", line 1, in top-level template code
  File "/usr/local/lib/python3.11/site-packages/jinja2/sandbox.py", line 326, in getattr
    value = getattr(obj, attribute)
            ^^^^^^^^^^^^^^^^^^^^^^^
  File "/usr/src/homeassistant/homeassistant/helpers/template.py", line 2266, in _fail_with_undefined_error
    raise ex
  File "/usr/src/homeassistant/homeassistant/helpers/template.py", line 2263, in _fail_with_undefined_error
    return super()._fail_with_undefined_error(*args, **kwargs)
           ^^^^^^^^^^^^^^^^^^^^^^^^^^^^^^^^^^^^^^^^^^^^^^^^^^^
jinja2.exceptions.UndefinedError: 'None' has no attribute 'attributes'

The above exception was the direct cause of the following exception:

Traceback (most recent call last):
  File "/usr/src/homeassistant/homeassistant/helpers/template.py", line 694, in async_render_to_info
    render_info._result = self.async_render(
                          ^^^^^^^^^^^^^^^^^^
  File "/usr/src/homeassistant/homeassistant/helpers/template.py", line 570, in async_render
    raise TemplateError(err) from err
homeassistant.exceptions.TemplateError: UndefinedError: 'None' has no attribute 'attributes'
2023-11-03 17:32:36.158 ERROR (MainThread) [homeassistant.helpers.template] Template variable error: 'None' has no attribute 'attributes' when rendering '{{ states.vacuum.hombot.attributes.status }}'
2023-11-03 17:32:36.159 ERROR (MainThread) [homeassistant.components.template.template_entity] TemplateError('UndefinedError: 'None' has no attribute 'attributes'') while processing template 'Template<template=({{ states.vacuum.hombot.attributes.status }}) renders=4>' for attribute '_attr_native_value' in entity 'sensor.hombot_status'
2023-11-03 17:32:36.164 ERROR (MainThread) [homeassistant.helpers.event] Error while processing template: Template<template=({% if states('sensor.medicine_hours_recent')|int > 23 %}
  {% set hours = states('sensor.medicine_hours_recent')|int - 24 %}
{% else %}
  {% set hours = states('sensor.medicine_hours_recent')|int %}
{% endif %}
  {% set minutes = states('sensor.medicine_minutes_recent')|int %}
{{hours|string + ":" + minutes|string }}) renders=2>
Traceback (most recent call last):
  File "/usr/src/homeassistant/homeassistant/helpers/template.py", line 568, in async_render
    render_result = _render_with_context(self.template, compiled, **kwargs)
                    ^^^^^^^^^^^^^^^^^^^^^^^^^^^^^^^^^^^^^^^^^^^^^^^^^^^^^^^
  File "/usr/src/homeassistant/homeassistant/helpers/template.py", line 2231, in _render_with_context
    return template.render(**kwargs)
           ^^^^^^^^^^^^^^^^^^^^^^^^^
  File "/usr/local/lib/python3.11/site-packages/jinja2/environment.py", line 1301, in render
    self.environment.handle_exception()
  File "/usr/local/lib/python3.11/site-packages/jinja2/environment.py", line 936, in handle_exception
    raise rewrite_traceback_stack(source=source)
  File "<template>", line 1, in top-level template code
  File "/usr/src/homeassistant/homeassistant/helpers/template.py", line 1944, in forgiving_int_filter
    raise_no_default("int", value)
  File "/usr/src/homeassistant/homeassistant/helpers/template.py", line 1626, in raise_no_default
    raise ValueError(
ValueError: Template error: int got invalid input 'unknown' when rendering template '{% if states('sensor.medicine_hours_recent')|int > 23 %}
  {% set hours = states('sensor.medicine_hours_recent')|int - 24 %}
{% else %}
  {% set hours = states('sensor.medicine_hours_recent')|int %}
{% endif %}
  {% set minutes = states('sensor.medicine_minutes_recent')|int %}
{{hours|string + ":" + minutes|string }}' but no default was specified

The above exception was the direct cause of the following exception:

Traceback (most recent call last):
  File "/usr/src/homeassistant/homeassistant/helpers/template.py", line 694, in async_render_to_info
    render_info._result = self.async_render(
                          ^^^^^^^^^^^^^^^^^^
  File "/usr/src/homeassistant/homeassistant/helpers/template.py", line 570, in async_render
    raise TemplateError(err) from err
homeassistant.exceptions.TemplateError: ValueError: Template error: int got invalid input 'unknown' when rendering template '{% if states('sensor.medicine_hours_recent')|int > 23 %}
  {% set hours = states('sensor.medicine_hours_recent')|int - 24 %}
{% else %}
  {% set hours = states('sensor.medicine_hours_recent')|int %}
{% endif %}
  {% set minutes = states('sensor.medicine_minutes_recent')|int %}
{{hours|string + ":" + minutes|string }}' but no default was specified
2023-11-03 17:32:36.173 ERROR (MainThread) [homeassistant.components.template.template_entity] TemplateError('ValueError: Template error: int got invalid input 'unknown' when rendering template '{% if states('sensor.medicine_hours_recent')|int > 23 %}
  {% set hours = states('sensor.medicine_hours_recent')|int - 24 %}
{% else %}
  {% set hours = states('sensor.medicine_hours_recent')|int %}
{% endif %}
  {% set minutes = states('sensor.medicine_minutes_recent')|int %}
{{hours|string + ":" + minutes|string }}' but no default was specified') while processing template 'Template<template=({% if states('sensor.medicine_hours_recent')|int > 23 %}
  {% set hours = states('sensor.medicine_hours_recent')|int - 24 %}
{% else %}
  {% set hours = states('sensor.medicine_hours_recent')|int %}
{% endif %}
  {% set minutes = states('sensor.medicine_minutes_recent')|int %}
{{hours|string + ":" + minutes|string }}) renders=4>' for attribute '_attr_native_value' in entity 'sensor.medicine_time_recent'
2023-11-03 17:32:36.693 WARNING (MainThread) [homeassistant.components.homeassistant.triggers.numeric_state] Error initializing 'Living rooms - lights on when blinds close' trigger: In 'numeric_state' condition: entity cover.living_room_blinds state 'closed' cannot be processed as a number
2023-11-03 17:32:36.694 WARNING (MainThread) [homeassistant.components.homeassistant.triggers.numeric_state] Error initializing 'Bedroom - lights off when blinds open' trigger: In 'numeric_state' condition: entity cover.bedroom_blinds state 'open' cannot be processed as a number
2023-11-03 17:32:41.889 WARNING (MainThread) [custom_components.hacs] You have 'ericpignet/home-assistant-lg_hombot' installed with HACS this repository has been removed from HACS, please consider removing it. Removal reason (Integration is missing a version, and is abandoned.)
2023-11-03 17:32:44.391 WARNING (Recorder) [homeassistant.components.sensor.recorder] The unit of sensor.openweathermap_rain (mm/h) cannot be converted to the unit of previously compiled statistics (mm). Generation of long term statistics will be suppressed unless the unit changes back to mm or a compatible unit. Go to https://my.home-assistant.io/redirect/developer_statistics to fix this
2023-11-03 17:32:44.392 WARNING (Recorder) [homeassistant.components.sensor.recorder] The unit of sensor.openweathermap_snow (mm/h) cannot be converted to the unit of previously compiled statistics (mm). Generation of long term statistics will be suppressed unless the unit changes back to mm or a compatible unit. Go to https://my.home-assistant.io/redirect/developer_statistics to fix this
2023-11-03 17:32:44.396 WARNING (Recorder) [homeassistant.components.sensor.recorder] The unit of sensor.home_precipitation (mm/h) cannot be converted to the unit of previously compiled statistics (mm). Generation of long term statistics will be suppressed unless the unit changes back to mm or a compatible unit. Go to https://my.home-assistant.io/redirect/developer_statistics to fix this
2023-11-03 17:32:49.213 ERROR (MainThread) [homeassistant.components.shell_command] Error running command: `/bin/bash pushupdates.sh`, return code: 128
NoneType: None
2023-11-03 17:33:09.430 WARNING (MainThread) [homeassistant.helpers.template] Template variable warning: 'title' is undefined when rendering '{{ title }}'
2023-11-03 17:33:09.432 WARNING (MainThread) [homeassistant.helpers.template] Template variable warning: 'title' is undefined when rendering '{{ title }}'
2023-11-03 17:33:09.434 WARNING (MainThread) [homeassistant.helpers.template] Template variable warning: 'title' is undefined when rendering '{{ title }}'
2023-11-03 17:33:09.858 WARNING (MainThread) [homeassistant.helpers.template] Template variable warning: 'title' is undefined when rendering '{{ title }}'
2023-11-03 17:33:09.912 WARNING (MainThread) [homeassistant.helpers.template] Template variable warning: 'title' is undefined when rendering '{{ title }}'
2023-11-03 17:33:09.981 WARNING (MainThread) [homeassistant.helpers.template] Template variable warning: 'title' is undefined when rendering '{{ title }}'
